Workbook

Sheet Test Cases
A1: ID | B1: Area | C1: Scenario | D1: Preconditions | E1: Steps | F1: Expected result | G1: Spec reference | H1: Priority | I1: Actual result | J1: Status | K1: Device/OS | L1: Tested on | M1: Notes / bug link
A2: SET-01 | B2: Setup | C2: Fresh clone and dependency install | D2: Node.js 22.18+ (22.x) and npm installed; network access. | E2: 1. git clone the repo into a new folder 2. cd into it 3. Run: npm ci | F2: npm ci completes without errors; node_modules created from package-lock.json. | G2: ALSO EXPECTED: "App runs from README instructions" | H2: High | J2: Pass
A3: SET-02 | B3: Setup | C3: Type check and automated test suites pass | D3: SET-01 passed. | E3: 1. npm run typecheck 2. npm run test:validation 3. npm run test:submit | F3: All three commands exit with code 0. test:validation prints FAIL lines for intentionally rejected samples; this is expected. | G3: STRETCH: "A few automated tests for validation or privacy switch" | H3: High | J3: Pass | M3: Record exit codes in Actual result.
A4: SET-03 | B4: Setup | C4: Start Expo and open in Expo Go without login | D4: SET-01 passed; phone and computer on same network; Expo Go (SDK 58) installed. | E4: 1. npm start 2. Scan the QR code with Expo Go (iOS: Camera app) 3. Wait for the bundle to load | F4: QR code shown in terminal; app loads on the phone without requiring an Expo login; screen shows the heading "Create event". | G4: Deliver: "runnable project ... + README (how to run)" | H4: High | J4: Pass | M4: If network blocks LAN, try: npx expo start --tunnel
A5: SET-04 | B5: Setup | C5: Optional setup script on a clean machine | D5: macOS/Linux/WSL machine; Bash and curl available. | E5: 1. bash scripts/setup.sh 2. Follow the final instructions printed | F5: Script reuses or installs Node 22 via nvm, runs npm ci, typecheck and both test suites, then prints "Setup complete. Start Expo from the repository root with: npm start". | G5: Own decision (README: Fresh-device setup) | H5: Low | J5: Pass
A6: IMG-01 | B6: Image | C6: Empty state on first load | D6: App open in Expo Go; fresh form (nothing entered). | E6: 1. Look at the image section at the top of the form | F6: Label "Event image"; dashed placeholder with "No image selected" and an "Add image" button; no error shown. | G6: 1) IMAGE: "No image yet → empty state" | H6: High | J6: Pass
A7: IMG-02 | B7: Image | C7: First-time permission prompt and allow | D7: Photo permission for Expo Go not yet decided (reinstall Expo Go or reset permissions). | E7: 1. Tap "Add image" 2. Allow photo access in the system prompt | F7: System photo-permission prompt appears; after allowing, the photo library opens showing images only. | G7: 1) IMAGE: "Add image" | H7: High | J7: Pass | M7: In Expo Go the permission belongs to Expo Go, not to this app.
A8: IMG-03 | B8: Image | C8: Pick an image shows preview | D8: App open in Expo Go; fresh form (nothing entered). Photo permission granted. | E8: 1. Tap "Add image" 2. Select a photo | F8: Placeholder disappears; selected photo shown as a 16:9 preview with "Change" and "Remove" buttons; no error. | G8: 1) IMAGE: "User picks/drops an image → preview shown" | H8: High | J8: Pass
A9: IMG-04 | B9: Image | C9: Change replaces the image | D9: An image is already selected (IMG-03). | E9: 1. Tap "Change" 2. Select a different photo | F9: Preview updates to the newly selected photo; Change/Remove still visible. | G9: 1) IMAGE: "show preview" | H9: Med | J9: Pass
A10: IMG-05 | B10: Image | C10: Cancel the picker keeps current state | D10: Run twice: once from empty state, once with an image selected. | E10: 1. Tap "Add image" (or "Change") 2. Close/cancel the picker without selecting | F10: Form returns unchanged: empty state stays empty, or previous preview stays; no error message appears. | G10: Own decision | H10: Med | J10: Pass
A11: IMG-06 | B11: Image | C11: Remove returns to empty state | D11: An image is selected. | E11: 1. Tap "Remove" | F11: Preview removed; "No image selected" placeholder with "Add image" returns; error "Please add an image" appears immediately (image validates on every change). | G11: 1) IMAGE: "User removes image → back to empty state" | H11: High | J11: Pass
A12: IMG-07 | B12: Image | C12: Permission denied shows clear error | D12: Photo permission not yet decided, or can still be asked. | E12: 1. Tap "Add image" 2. Deny / Don't Allow in the system prompt | F12: Error "Allow photo access to add an image" shown; picker does not open; no "Open Settings" button while the system can still ask. | G12: 1) IMAGE: "Picker/permission fails → clear error message" | H12: High | J12: Pass | M12: Android may show Open Settings after the second denial (OS no longer asks).
A13: IMG-08 | B13: Image | C13: Permanently denied shows Open Settings | D13: Photo access for Expo Go denied in system settings (cannot ask again). | E13: 1. Tap "Add image" 2. Tap "Open Settings" 3. Grant photo access, return to Expo Go 4. Tap "Add image" again | F13: Step 1: "Allow photo access to add an image" plus an "Open Settings" button. Step 2: device settings open. Step 4: picker opens; error and button disappear. | G13: 1) IMAGE: "Picker/permission fails → clear error message" | H13: High | J13: Pass
A14: IMG-09 | B14: Image | C14: Submit without image is blocked | D14: No image; Title, Short and Long description valid. Privacy Public. | E14: 1. Tap Submit | F14: No success; "Please add an image" shown under the image section; summary "Please fix 1 field". | G14: 1) IMAGE: "submit not allowed"; Validation: Required | H14: High | J14: Pass
A15: TTL-01 | B15: Title | C15: No premature error; helper and counter | D15: App open in Expo Go; fresh form (nothing entered). | E15: 1. Tap into Title, type "a" (do not leave the field) | F15: No error while typing before first blur; helper "3–80 characters." below field; counter shows 1/80. | G15: Own decision (README: validation on first blur, then change) | H15: Med | J15: Pass
A16: TTL-02 | B16: Title | C16: Empty or spaces-only title is invalid | D16: App open in Expo Go; fresh form (nothing entered). | E16: 1. Tap Title, leave empty, tap elsewhere 2. Type 3 spaces, tap elsewhere | F16: Both cases: "Title must be at least 3 characters" with red field border. | G16: 2) TITLE: "Empty title → invalid", "Spaces only → invalid" | H16: High | J16: Pass
A17: TTL-03 | B17: Title | C17: Below minimum, then live correction | D17: App open in Expo Go; fresh form (nothing entered). | E17: 1. Type "ab", tap elsewhere 2. Tap back in and type "c" | F17: Step 1: "Title must be at least 3 characters". Step 2: error clears immediately while typing (re-validates on change). | G17: 2) TITLE: "Min length ... (example: min 3)"; "Show error ... on input" | H17: High | J17: Pass
A18: TTL-04 | B18: Title | C18: Leading/trailing spaces are trimmed | D18: App open in Expo Go; fresh form (nothing entered). | E18: 1. Type " ab " (2 spaces each side), tap elsewhere 2. Change to " Picnic " and complete a valid submit | F18: Step 1: invalid ("Title must be at least 3 characters"); counter shows 6/80 (counts raw text). Step 2: logged payload title is "Picnic" (trimmed). | G18: 2) TITLE: "Trim before validate/submit" | H18: High | J18: Pass
A19: TTL-05 | B19: Title | C19: Maximum length 80 | D19: App open in Expo Go; fresh form (nothing entered). | E19: 1. Type or paste exactly 80 characters 2. Try to type an 81st character 3. Paste a 100-character text into an empty Title | F19: 80 characters accepted with no error, counter 80/80; extra characters cannot be entered; paste is cut to 80. | G19: 2) TITLE: "Very long title → handle with a max length" | H19: Med | J19: Pass | M19: verify: paste truncation behaviour per platform.
A20: SD-01 | B20: Short description | C20: Field layout, helper and counter | D20: App open in Expo Go; fresh form (nothing entered). | E20: 1. Look at the Short description field 2. Type a few characters | F20: Multiline input; helper "10–200 characters. English only."; counter updates (e.g. 5/200). | G20: 3) DESCRIPTION: "Multiline OK for short and long" | H20: Low | J20: Pass
A21: SD-02 | B21: Short description | C21: Empty, spaces-only and below-minimum invalid; 10 valid | D21: App open in Expo Go; fresh form (nothing entered). | E21: 1. Leave empty, tap elsewhere 2. Type spaces only 3. Type 9 characters ("Join us a") 4. Add 1 character (10 total) 5. Try " Join us now " (padded) | F21: Steps 1-3: "Short description must be at least 10 characters". Step 4: error clears. Step 5: valid (trimmed length 11); payload value is trimmed. | G21: 3) DESCRIPTION: "Empty / Spaces only / Too short → invalid"; "Trim" | H21: High | J21: Pass
A22: SD-03 | B22: Short description | C22: Line breaks allowed; max 200 | D22: App open in Expo Go; fresh form (nothing entered). | E22: 1. Type two lines separated by Return (each > 5 chars) 2. Paste 250 characters | F22: Step 1: valid, no error. Step 2: input stops at 200, counter 200/200, no error. | G22: 3) DESCRIPTION: "Multiline OK"; Own decision (max 200) | H22: Med | J22: Pass
A23: SD-04 | B23: Short description | C23: Non-English text rejected | D23: App open in Expo Go; fresh form (nothing entered). | E23: 1. Type "Mời mọi người tham gia" 2. Replace with "Café meetup tonight" 3. Replace with "Picnic time 🎉 for all" | F23: Each case: "Short description must be in English" (only printable ASCII and line breaks allowed). | G23: 3) DESCRIPTION: "Short: only English allowed" | H23: High | J23: Pass
A24: SD-05 | B24: Short description | C24: iOS smart punctuation (apostrophe/quotes/dash) | D24: iOS device with default keyboard (Smart Punctuation on). | E24: 1. Type: Don't miss our "great" picnic -- all welcome | F24: Per spec English text should be accepted. Code allows printable ASCII only, so iOS curly ’ “ ” or em dash may trigger "Short description must be in English". | G24: 3) DESCRIPTION: "Short: only English allowed" | H24: Med | J24: Pass | M24: verify: likely device-only finding; log in Bugs if rejected.
A25: LD-01 | B25: Long description | C25: Empty, spaces-only and minimum boundary | D25: App open in Expo Go; fresh form (nothing entered). | E25: 1. Leave empty, tap elsewhere 2. Type spaces only 3. Type 19 characters 4. Add 1 character (20) | F25: Steps 1-3: "Long description must be at least 20 characters". Step 4: error clears; helper "20–2000 characters." | G25: 3) DESCRIPTION: "Too short → invalid" (example long min 20) | H25: High | J25: Pass
A26: LD-02 | B26: Long description | C26: Any language, symbols, numbers, emoji, multiline | D26: App open in Expo Go; fresh form (nothing entered). | E26: 1. Type multiline text mixing Vietnamese, emoji, numbers and symbols (≥ 20 chars), e.g. "Gặp nhau lúc 10h 🎉 #picnic @park" + Return + more text | F26: Accepted with no error; text shown exactly as typed. | G26: 3) DESCRIPTION: "Long: any symbols, any languages, numbers allowed" | H26: High | J26: Not run
A27: LD-03 | B27: Long description | C27: Maximum length 2000 | D27: App open in Expo Go; fresh form (nothing entered). | E27: 1. Paste a text longer than 2000 characters | F27: Input stops at 2000; counter 2000/2000; no error; field scrolls internally. | G27: Own decision (max 2000) | H27: Low | J27: Pass | M27: Emoji count as 2 characters in the counter.
A28: PRV-01 | B28: Privacy | C28: Starts unselected; no list shown | D28: App open in Expo Go; fresh form (nothing entered). | E28: 1. Scroll to Privacy | F28: "Public" and "Private" both unselected; no helper text; neither Communities nor Invites section visible. | G28: 4) VISIBILITY: "Choice: public | private"; Own decision (start unselected) | H28: High | J28: Not run
A29: PRV-02 | B29: Privacy | C29: Submit with no choice fails | D29: Image picked; Title, Short and Long description valid. | E29: 1. Leave Privacy unselected 2. Tap Submit | F29: No success; "Choose public or private" under Privacy; summary "Please fix 1 field". | G29: 4) VISIBILITY: "Privacy not chosen → submit fails; tell user to choose public or private" | H29: High | J29: Not run
A30: PRV-03 | B30: Privacy | C30: Select Public | D30: App open in Expo Go; fresh form (nothing entered). | E30: 1. Tap "Public" | F30: Public highlighted (blue); helper "Shared with the selected communities."; Communities section shown; no Invites section; any privacy error cleared. | G30: 4) PUBLIC: "Do not require invites; do not show invite UI as required" | H30: High | J30: Not run | M30: Helper wording vs 'None selected: visible to everyone' - check it reads clearly.
A31: PRV-04 | B31: Privacy | C31: Select Private | D31: App open in Expo Go; fresh form (nothing entered). | E31: 1. Tap "Private" | F31: Private highlighted; helper "Invite only."; Invites section with email input, Add button and Saved emails shown; Communities hidden. | G31: 4) PRIVATE: "Communities hidden" | H31: High | J31: Not run
A32: PRV-05 | B32: Privacy | C32: Public → Private: communities stop driving logic | D32: Image picked; Title, Short and Long description valid. Public with 2 communities selected. | E32: 1. Switch to Private 2. Tap Submit (no invites) 3. Add 1 invite, Submit 4. Check Metro log | F32: Step 2: fails with "Invite at least 1 person to a private event". Step 3: success. Payload has privacy "private", invites, and no communities key. | G32: 4) SWITCH: "Public → private: community selection must not keep driving logic" | H32: High | J32: Not run
A33: PRV-06 | B33: Privacy | C33: Private → Public: invites stop blocking | D33: Image picked; Title, Short and Long description valid. Private with 0 invites; Submit tapped so invite error is shown. | E33: 1. Switch to Public 2. Tap Submit 3. Check Metro log | F33: Invite error disappears on switch; submit succeeds; payload has privacy "public", communities, and no invites key. | G33: 4) SWITCH: "Private → public: invites must not keep blocking public submit" | H33: High | J33: Not run
A34: PRV-07 | B34: Privacy | C34: No ghost errors; lists preserved across switches | D34: Image picked; Title, Short and Long description valid. | E34: 1. Private: add 2 invites; type "draft@x" without adding 2. Switch to Public, select 1 community 3. Switch back to Private 4. Switch to Public again | F34: Step 3: the 2 invites are still listed; no stale errors; unadded draft text is cleared. Step 4: the community is still selected. Only the active mode's rules apply. | G34: 4) SWITCH: "After switch, rules of the new mode apply (no ghost/hidden field bugs)" | H34: High | J34: Pass | M34: Draft text lost on switch is expected (input is remounted).
A35: PUB-01 | B35: Public | C35: Communities section content | D35: Privacy = Public. | E35: 1. Look at the Communities section | F35: Label "Communities (optional)"; 5 options: Nature Explorers, Arts and Crafts, Sports Club, Book Lovers, Local Families; status text "None selected: visible to everyone". | G35: 4) PUBLIC: "Optional communities multi-select from data"; "No communities = visible to everyone" | H35: High | J35: Pass
A36: PUB-02 | B36: Public | C36: Multi-select and deselect | D36: Privacy = Public. | E36: 1. Tap Nature Explorers and Book Lovers 2. Tap Nature Explorers again | F36: Step 1: both highlighted with "Selected" tag; text "2 selected". Step 2: Nature Explorers deselected; "1 selected". | G36: 4) PUBLIC: "Optional communities multi-select" | H36: High | J36: Pass
A37: PUB-03 | B37: Public | C37: Submit public with no communities | D37: Image picked; Title, Short and Long description valid. Privacy = Public, none selected. | E37: 1. Tap Submit 2. Check Metro log | F37: Success; payload privacy "public" and communities [] (empty = visible to everyone); no invites key. | G37: 4) PUBLIC: "Valid image + title + description + public → submit succeeds" | H37: High | J37: Pass
A38: PUB-04 | B38: Public | C38: Submit public with selected communities | D38: Image picked; Title, Short and Long description valid. Public; Sports Club and Local Families selected. | E38: 1. Tap Submit 2. Check Metro log | F38: Success; payload communities ["sports-club", "local-families"]; no invites key. | G38: SUBMIT: "Payload should include ... communities (public)" | H38: High | I38: Event payload: {"communities": ["sports-club", "local-families"], "image": {"fileName": "IMG_0005.jpg", "mimeType": "image/jpeg", "uri": "file:///Users/jmacmini/Library/Developer/CoreSimulator/Devices/92D58B13-5897-4C60-BC94-8DD798EEADC2/data/Containers/Data/Application/8DEFE3F1-F4D8-471E-87EC-BD79D74E319C/Library/Caches/ImagePicker/98F82059-94B8-46D1-8C09-3BAA1D891ACF.jpg"}, "longDescription": "22222222222222222222", "privacy": "public", "shortDescription": "1111111111", "title": "123"} | J38: Pass
A39: PUB-05 | B39: Public | C39: Leftover private state does not block public | D39: Image picked; Title, Short and Long description valid. | E39: 1. Private: add 1 invite, type "bad@" and tap Add (error shown) 2. Switch to Public 3. Submit | F39: Success; no invite errors shown; payload has no invites key. | G39: 4) VISIBILITY Validation: "Public: ... invites not required" | H39: High | I39: LOG Event payload: {"communities": [], "image": {"fileName": "IMG_0005.jpg", "mimeType": "image/jpeg", "uri": "file:///Users/jmacmini/Library/Developer/CoreSimulator/Devices/92D58B13-5897-4C60-BC94-8DD798EEADC2/data/Containers/Data/Application/8DEFE3F1-F4D8-471E-87EC-BD79D74E319C/Library/Caches/ImagePicker/CD8A790A-B0DD-42DB-933E-E4B7EB4BBE6B.jpg"}, "longDescription": "44444444444444444444", "privacy": "public", "shortDescription": "3333333333", "title": "345"} | J39: Pass
A40: INV-01 | B40: Private invites | C40: Zero invites fails | D40: Image picked; Title, Short and Long description valid. Privacy = Private, no invites. | E40: 1. Tap Submit | F40: No success; "Invite at least 1 person to a private event" under Invites; summary "Please fix 1 field". | G40: 4) PRIVATE: "Zero invites → submit fails" | H40: High | J40: Pass
...

Sheet Summary
A1: Create Event Form – Device / Integration Test Summary
A2: Fill the yellow cells. All counts update from the Status column on the Test Cases tab.
A4: Test run details | D4: Bugs | E4: Count
A5: Tester name | D5: Open | E5: =COUNTIF(Bugs!$F$2:$F$300,D5) -> 0
A6: Device model | D6: In progress | E6: =COUNTIF(Bugs!$F$2:$F$300,D6) -> 0
A7: OS version | D7: Fixed | E7: =COUNTIF(Bugs!$F$2:$F$300,D7) -> 0
A8: Expo Go version | D8: Won't fix | E8: =COUNTIF(Bugs!$F$2:$F$300,D8) -> 0
A9: Node.js version
A10: Commit SHA / tag tested
A11: Test date
A13: Overall | B13: Count
A14: Not run | B14: =COUNTIF('Test Cases'!$J$2:$J$300,A14) -> 25
A15: Pass | B15: =COUNTIF('Test Cases'!$J$2:$J$300,A15) -> 47
A16: Fail | B16: =COUNTIF('Test Cases'!$J$2:$J$300,A16) -> 0
A17: Blocked | B17: =COUNTIF('Test Cases'!$J$2:$J$300,A17) -> 0
A18: N/A | B18: =COUNTIF('Test Cases'!$J$2:$J$300,A18) -> 0
A19: Total test cases | B19: =COUNTA('Test Cases'!$A$2:$A$300) -> 72
A20: Executed (Pass + Fail + Blocked) | B20: =B15+B16+B17 -> 47
A21: Pass rate (of executed) | B21: =IFERROR(B15/B20,0) -> 1
A22: Executed % (of applicable) | B22: =IFERROR(B20/(B19-B18),0) -> 0.65277778
A23: Blank or unknown status (should be 0) | B23: =B19-SUM(B14:B18) -> 0
A25: Area | B25: Total | C25: Pass | D25: Fail | E25: Blocked | F25: Not run | G25: N/A | H25: Pass rate
A26: Setup | B26: =COUNTIF('Test Cases'!$B$2:$B$300,$A26) -> 4 | C26: =COUNTIFS('Test Cases'!$B$2:$B$300,$A26,'Test Cases'!$J$2:$J$300,"Pass") -> 4 | D26: =COUNTIFS('Test Cases'!$B$2:$B$300,$A26,'Test Cases'!$J$2:$J$300,"Fail") -> 0 | E26: =COUNTIFS('Test Cases'!$B$2:$B$300,$A26,'Test Cases'!$J$2:$J$300,"Blocked") -> 0 | F26: =COUNTIFS('Test Cases'!$B$2:$B$300,$A26,'Test Cases'!$J$2:$J$300,"Not run") -> 0 | G26: =COUNTIFS('Test Cases'!$B$2:$B$300,$A26,'Test Cases'!$J$2:$J$300,"N/A") -> 0 | H26: =IFERROR(C26/(C26+D26+E26),0) -> 1
A27: Image | B27: =COUNTIF('Test Cases'!$B$2:$B$300,$A27) -> 9 | C27: =COUNTIFS('Test Cases'!$B$2:$B$300,$A27,'Test Cases'!$J$2:$J$300,"Pass") -> 9 | D27: =COUNTIFS('Test Cases'!$B$2:$B$300,$A27,'Test Cases'!$J$2:$J$300,"Fail") -> 0 | E27: =COUNTIFS('Test Cases'!$B$2:$B$300,$A27,'Test Cases'!$J$2:$J$300,"Blocked") -> 0 | F27: =COUNTIFS('Test Cases'!$B$2:$B$300,$A27,'Test Cases'!$J$2:$J$300,"Not run") -> 0 | G27: =COUNTIFS('Test Cases'!$B$2:$B$300,$A27,'Test Cases'!$J$2:$J$300,"N/A") -> 0 | H27: =IFERROR(C27/(C27+D27+E27),0) -> 1
A28: Title | B28: =COUNTIF('Test Cases'!$B$2:$B$300,$A28) -> 5 | C28: =COUNTIFS('Test Cases'!$B$2:$B$300,$A28,'Test Cases'!$J$2:$J$300,"Pass") -> 5 | D28: =COUNTIFS('Test Cases'!$B$2:$B$300,$A28,'Test Cases'!$J$2:$J$300,"Fail") -> 0 | E28: =COUNTIFS('Test Cases'!$B$2:$B$300,$A28,'Test Cases'!$J$2:$J$300,"Blocked") -> 0 | F28: =COUNTIFS('Test Cases'!$B$2:$B$300,$A28,'Test Cases'!$J$2:$J$300,"Not run") -> 0 | G28: =COUNTIFS('Test Cases'!$B$2:$B$300,$A28,'Test Cases'!$J$2:$J$300,"N/A") -> 0 | H28: =IFERROR(C28/(C28+D28+E28),0) -> 1
A29: Short description | B29: =COUNTIF('Test Cases'!$B$2:$B$300,$A29) -> 5 | C29: =COUNTIFS('Test Cases'!$B$2:$B$300,$A29,'Test Cases'!$J$2:$J$300,"Pass") -> 5 | D29: =COUNTIFS('Test Cases'!$B$2:$B$300,$A29,'Test Cases'!$J$2:$J$300,"Fail") -> 0 | E29: =COUNTIFS('Test Cases'!$B$2:$B$300,$A29,'Test Cases'!$J$2:$J$300,"Blocked") -> 0 | F29: =COUNTIFS('Test Cases'!$B$2:$B$300,$A29,'Test Cases'!$J$2:$J$300,"Not run") -> 0 | G29: =COUNTIFS('Test Cases'!$B$2:$B$300,$A29,'Test Cases'!$J$2:$J$300,"N/A") -> 0 | H29: =IFERROR(C29/(C29+D29+E29),0) -> 1
A30: Long description | B30: =COUNTIF('Test Cases'!$B$2:$B$300,$A30) -> 3 | C30: =COUNTIFS('Test Cases'!$B$2:$B$300,$A30,'Test Cases'!$J$2:$J$300,"Pass") -> 2 | D30: =COUNTIFS('Test Cases'!$B$2:$B$300,$A30,'Test Cases'!$J$2:$J$300,"Fail") -> 0 | E30: =COUNTIFS('Test Cases'!$B$2:$B$300,$A30,'Test Cases'!$J$2:$J$300,"Blocked") -> 0 | F30: =COUNTIFS('Test Cases'!$B$2:$B$300,$A30,'Test Cases'!$J$2:$J$300,"Not run") -> 1 | G30: =COUNTIFS('Test Cases'!$B$2:$B$300,$A30,'Test Cases'!$J$2:$J$300,"N/A") -> 0 | H30: =IFERROR(C30/(C30+D30+E30),0) -> 1
A31: Privacy | B31: =COUNTIF('Test Cases'!$B$2:$B$300,$A31) -> 7 | C31: =COUNTIFS('Test Cases'!$B$2:$B$300,$A31,'Test Cases'!$J$2:$J$300,"Pass") -> 1 | D31: =COUNTIFS('Test Cases'!$B$2:$B$300,$A31,'Test Cases'!$J$2:$J$300,"Fail") -> 0 | E31: =COUNTIFS('Test Cases'!$B$2:$B$300,$A31,'Test Cases'!$J$2:$J$300,"Blocked") -> 0 | F31: =COUNTIFS('Test Cases'!$B$2:$B$300,$A31,'Test Cases'!$J$2:$J$300,"Not run") -> 6 | G31: =COUNTIFS('Test Cases'!$B$2:$B$300,$A31,'Test Cases'!$J$2:$J$300,"N/A") -> 0 | H31: =IFERROR(C31/(C31+D31+E31),0) -> 1
A32: Public | B32: =COUNTIF('Test Cases'!$B$2:$B$300,$A32) -> 5 | C32: =COUNTIFS('Test Cases'!$B$2:$B$300,$A32,'Test Cases'!$J$2:$J$300,"Pass") -> 5 | D32: =COUNTIFS('Test Cases'!$B$2:$B$300,$A32,'Test Cases'!$J$2:$J$300,"Fail") -> 0 | E32: =COUNTIFS('Test Cases'!$B$2:$B$300,$A32,'Test Cases'!$J$2:$J$300,"Blocked") -> 0 | F32: =COUNTIFS('Test Cases'!$B$2:$B$300,$A32,'Test Cases'!$J$2:$J$300,"Not run") -> 0 | G32: =COUNTIFS('Test Cases'!$B$2:$B$300,$A32,'Test Cases'!$J$2:$J$300,"N/A") -> 0 | H32: =IFERROR(C32/(C32+D32+E32),0) -> 1
A33: Private invites | B33: =COUNTIF('Test Cases'!$B$2:$B$300,$A33) -> 12 | C33: =COUNTIFS('Test Cases'!$B$2:$B$300,$A33,'Test Cases'!$J$2:$J$300,"Pass") -> 8 | D33: =COUNTIFS('Test Cases'!$B$2:$B$300,$A33,'Test Cases'!$J$2:$J$300,"Fail") -> 0 | E33: =COUNTIFS('Test Cases'!$B$2:$B$300,$A33,'Test Cases'!$J$2:$J$300,"Blocked") -> 0 | F33: =COUNTIFS('Test Cases'!$B$2:$B$300,$A33,'Test Cases'!$J$2:$J$300,"Not run") -> 4 | G33: =COUNTIFS('Test Cases'!$B$2:$B$300,$A33,'Test Cases'!$J$2:$J$300,"N/A") -> 0 | H33: =IFERROR(C33/(C33+D33+E33),0) -> 1
A34: Submit | B34: =COUNTIF('Test Cases'!$B$2:$B$300,$A34) -> 9 | C34: =COUNTIFS('Test Cases'!$B$2:$B$300,$A34,'Test Cases'!$J$2:$J$300,"Pass") -> 8 | D34: =COUNTIFS('Test Cases'!$B$2:$B$300,$A34,'Test Cases'!$J$2:$J$300,"Fail") -> 0 | E34: =COUNTIFS('Test Cases'!$B$2:$B$300,$A34,'Test Cases'!$J$2:$J$300,"Blocked") -> 0 | F34: =COUNTIFS('Test Cases'!$B$2:$B$300,$A34,'Test Cases'!$J$2:$J$300,"Not run") -> 1 | G34: =COUNTIFS('Test Cases'!$B$2:$B$300,$A34,'Test Cases'!$J$2:$J$300,"N/A") -> 0 | H34: =IFERROR(C34/(C34+D34+E34),0) -> 1
A35: Keyboard & layout | B35: =COUNTIF('Test Cases'!$B$2:$B$300,$A35) -> 6 | C35: =COUNTIFS('Test Cases'!$B$2:$B$300,$A35,'Test Cases'!$J$2:$J$300,"Pass") -> 0 | D35: =COUNTIFS('Test Cases'!$B$2:$B$300,$A35,'Test Cases'!$J$2:$J$300,"Fail") -> 0 | E35: =COUNTIFS('Test Cases'!$B$2:$B$300,$A35,'Test Cases'!$J$2:$J$300,"Blocked") -> 0 | F35: =COUNTIFS('Test Cases'!$B$2:$B$300,$A35,'Test Cases'!$J$2:$J$300,"Not run") -> 6 | G35: =COUNTIFS('Test Cases'!$B$2:$B$300,$A35,'Test Cases'!$J$2:$J$300,"N/A") -> 0 | H35: =IFERROR(C35/(C35+D35+E35),0) -> 0
A36: Accessibility | B36: =COUNTIF('Test Cases'!$B$2:$B$300,$A36) -> 4 | C36: =COUNTIFS('Test Cases'!$B$2:$B$300,$A36,'Test Cases'!$J$2:$J$300,"Pass") -> 0 | D36: =COUNTIFS('Test Cases'!$B$2:$B$300,$A36,'Test Cases'!$J$2:$J$300,"Fail") -> 0 | E36: =COUNTIFS('Test Cases'!$B$2:$B$300,$A36,'Test Cases'!$J$2:$J$300,"Blocked") -> 0 | F36: =COUNTIFS('Test Cases'!$B$2:$B$300,$A36,'Test Cases'!$J$2:$J$300,"Not run") -> 4 | G36: =COUNTIFS('Test Cases'!$B$2:$B$300,$A36,'Test Cases'!$J$2:$J$300,"N/A") -> 0 | H36: =IFERROR(C36/(C36+D36+E36),0) -> 0
A37: Optional | B37: =COUNTIF('Test Cases'!$B$2:$B$300,$A37) -> 3 | C37: =COUNTIFS('Test Cases'!$B$2:$B$300,$A37,'Test Cases'!$J$2:$J$300,"Pass") -> 0 | D37: =COUNTIFS('Test Cases'!$B$2:$B$300,$A37,'Test Cases'!$J$2:$J$300,"Fail") -> 0 | E37: =COUNTIFS('Test Cases'!$B$2:$B$300,$A37,'Test Cases'!$J$2:$J$300,"Blocked") -> 0 | F37: =COUNTIFS('Test Cases'!$B$2:$B$300,$A37,'Test Cases'!$J$2:$J$300,"Not run") -> 3 | G37: =COUNTIFS('Test Cases'!$B$2:$B$300,$A37,'Test Cases'!$J$2:$J$300,"N/A") -> 0 | H37: =IFERROR(C37/(C37+D37+E37),0) -> 0
A38: Total | B38: =SUM(B26:B37) -> 72 | C38: =SUM(C26:C37) -> 47 | D38: =SUM(D26:D37) -> 0 | E38: =SUM(E26:E37) -> 0 | F38: =SUM(F26:F37) -> 25 | G38: =SUM(G26:G37) -> 0 | H38: =IFERROR(C38/(C38+D38+E38),0) -> 1

Sheet Bugs
A1: Bug ID | B1: Linked test ID | C1: Title / Description | D1: Steps to reproduce | E1: Severity | F1: Status | G1: Fix commit | H1: Date found
A2: BUG-01
A3: BUG-02
A4: BUG-03
A5: BUG-04
A6: BUG-05
A7: BUG-06
A8: BUG-07
A9: BUG-08
A10: BUG-09
A11: BUG-10
A12: BUG-11
A13: BUG-12
... A31: BUG-30
